[2025-06-01T09:50:42.838+0000] {taskinstance.py:1103} INFO - Dependencies all met for dep_context=non-requeueable deps ti=<TaskInstance: first_dag.random_dice scheduled__2021-03-02T00:00:00+00:00 [queued]>
[2025-06-01T09:50:42.844+0000] {taskinstance.py:1103} INFO - Dependencies all met for dep_context=requeueable deps ti=<TaskInstance: first_dag.random_dice scheduled__2021-03-02T00:00:00+00:00 [queued]>
[2025-06-01T09:50:42.844+0000] {taskinstance.py:1308} INFO - Starting attempt 1 of 3
[2025-06-01T09:50:42.855+0000] {taskinstance.py:1327} INFO - Executing <Task(PythonOperator): random_dice> on 2021-03-02 00:00:00+00:00
[2025-06-01T09:50:42.859+0000] {standard_task_runner.py:57} INFO - Started process 3943 to run task
[2025-06-01T09:50:42.861+0000] {standard_task_runner.py:84} INFO - Running: ['***', 'tasks', 'run', 'first_dag', 'random_dice', 'scheduled__2021-03-02T00:00:00+00:00', '--job-id', '97', '--raw', '--subdir', 'DAGS_FOLDER/my_first_dag.py', '--cfg-path', '/tmp/tmp2zuslzrd']
[2025-06-01T09:50:42.863+0000] {standard_task_runner.py:85} INFO - Job 97: Subtask random_dice
[2025-06-01T09:50:42.893+0000] {task_command.py:410} INFO - Running <TaskInstance: first_dag.random_dice scheduled__2021-03-02T00:00:00+00:00 [running]> on host 27c4b93144a0
[2025-06-01T09:50:42.960+0000] {taskinstance.py:1547} INFO - Exporting env vars: AIRFLOW_CTX_DAG_OWNER='***' AIRFLOW_CTX_DAG_ID='first_dag' AIRFLOW_CTX_TASK_ID='random_dice' AIRFLOW_CTX_EXECUTION_DATE='2021-03-02T00:00:00+00:00' AIRFLOW_CTX_TRY_NUMBER='1' AIRFLOW_CTX_DAG_RUN_ID='scheduled__2021-03-02T00:00:00+00:00'
[2025-06-01T09:50:42.960+0000] {taskinstance.py:1824} ERROR - Task failed with exception
Traceback (most recent call last):
  File "/home/airflow/.local/lib/python3.7/site-packages/airflow/operators/python.py", line 181, in execute
    return_value = self.execute_callable()
  File "/home/airflow/.local/lib/python3.7/site-packages/airflow/operators/python.py", line 198, in execute_callable
    return self.python_callable(*self.op_args, **self.op_kwargs)
  File "/opt/airflow/dags/my_first_dag.py", line 18, in random_dice
    raise ValueError(f'Odd {val}')
ValueError: Odd 3
[2025-06-01T09:50:42.966+0000] {taskinstance.py:1350} INFO - Marking task as UP_FOR_RETRY. dag_id=first_dag, task_id=random_dice, execution_date=20210302T000000, start_date=20250601T095042, end_date=20250601T095042
[2025-06-01T09:50:42.974+0000] {standard_task_runner.py:109} ERROR - Failed to execute job 97 for task random_dice (Odd 3; 3943)
[2025-06-01T09:50:42.993+0000] {local_task_job_runner.py:225} INFO - Task exited with return code 1
[2025-06-01T09:50:43.006+0000] {taskinstance.py:2653} INFO - 0 downstream tasks scheduled from follow-on schedule check
