[2025-06-01T16:37:10.826+0000] {taskinstance.py:1103} INFO - Dependencies all met for dep_context=non-requeueable deps ti=<TaskInstance: second_dag.save_data_task scheduled__2025-02-05T00:00:00+00:00 [queued]>
[2025-06-01T16:37:10.858+0000] {taskinstance.py:1103} INFO - Dependencies all met for dep_context=requeueable deps ti=<TaskInstance: second_dag.save_data_task scheduled__2025-02-05T00:00:00+00:00 [queued]>
[2025-06-01T16:37:10.860+0000] {taskinstance.py:1308} INFO - Starting attempt 1 of 3
[2025-06-01T16:37:10.879+0000] {taskinstance.py:1327} INFO - Executing <Task(PythonOperator): save_data_task> on 2025-02-05 00:00:00+00:00
[2025-06-01T16:37:10.888+0000] {standard_task_runner.py:57} INFO - Started process 75089 to run task
[2025-06-01T16:37:10.891+0000] {standard_task_runner.py:84} INFO - Running: ['***', 'tasks', 'run', 'second_dag', 'save_data_task', 'scheduled__2025-02-05T00:00:00+00:00', '--job-id', '4420', '--raw', '--subdir', 'DAGS_FOLDER/my_second_dag.py', '--cfg-path', '/tmp/tmpu4l9dy6j']
[2025-06-01T16:37:10.894+0000] {standard_task_runner.py:85} INFO - Job 4420: Subtask save_data_task
[2025-06-01T16:37:10.934+0000] {task_command.py:410} INFO - Running <TaskInstance: second_dag.save_data_task scheduled__2025-02-05T00:00:00+00:00 [running]> on host 27c4b93144a0
[2025-06-01T16:37:11.225+0000] {taskinstance.py:1547} INFO - Exporting env vars: AIRFLOW_CTX_DAG_OWNER='***' AIRFLOW_CTX_DAG_ID='second_dag' AIRFLOW_CTX_TASK_ID='save_data_task' AIRFLOW_CTX_EXECUTION_DATE='2025-02-05T00:00:00+00:00' AIRFLOW_CTX_TRY_NUMBER='1' AIRFLOW_CTX_DAG_RUN_ID='scheduled__2025-02-05T00:00:00+00:00'
[2025-06-01T16:37:11.240+0000] {my_second_dag.py:51} INFO - Fetching value USD: 98.5336
[2025-06-01T16:37:11.251+0000] {base.py:73} INFO - Using connection ID 'pg_database' for task execution.
[2025-06-01T16:37:11.261+0000] {logging_mixin.py:150} WARNING - /home/***/.local/lib/python3.7/site-packages/***/utils/context.py:313 AirflowContextDeprecationWarning: Accessing 'execution_date' from the template is deprecated and will be removed in a future version. Please use 'data_interval_start' or 'logical_date' instead.
[2025-06-01T16:37:11.263+0000] {my_second_dag.py:69} INFO - Data saved successfully.
[2025-06-01T16:37:11.263+0000] {python.py:183} INFO - Done. Returned value was: None
[2025-06-01T16:37:11.271+0000] {taskinstance.py:1350} INFO - Marking task as SUCCESS. dag_id=second_dag, task_id=save_data_task, execution_date=20250205T000000, start_date=20250601T163710, end_date=20250601T163711
[2025-06-01T16:37:11.304+0000] {local_task_job_runner.py:225} INFO - Task exited with return code 0
[2025-06-01T16:37:11.319+0000] {taskinstance.py:2653} INFO - 0 downstream tasks scheduled from follow-on schedule check
