[2025-06-01T16:11:14.257+0000] {taskinstance.py:1103} INFO - Dependencies all met for dep_context=non-requeueable deps ti=<TaskInstance: second_dag.save_data_task scheduled__2021-05-05T00:00:00+00:00 [queued]>
[2025-06-01T16:11:14.293+0000] {taskinstance.py:1103} INFO - Dependencies all met for dep_context=requeueable deps ti=<TaskInstance: second_dag.save_data_task scheduled__2021-05-05T00:00:00+00:00 [queued]>
[2025-06-01T16:11:14.293+0000] {taskinstance.py:1308} INFO - Starting attempt 2 of 3
[2025-06-01T16:11:14.333+0000] {taskinstance.py:1327} INFO - Executing <Task(PythonOperator): save_data_task> on 2021-05-05 00:00:00+00:00
[2025-06-01T16:11:14.348+0000] {standard_task_runner.py:57} INFO - Started process 34426 to run task
[2025-06-01T16:11:14.376+0000] {standard_task_runner.py:84} INFO - Running: ['***', 'tasks', 'run', 'second_dag', 'save_data_task', 'scheduled__2021-05-05T00:00:00+00:00', '--job-id', '1593', '--raw', '--subdir', 'DAGS_FOLDER/my_second_dag.py', '--cfg-path', '/tmp/tmphdsko0ix']
[2025-06-01T16:11:14.379+0000] {standard_task_runner.py:85} INFO - Job 1593: Subtask save_data_task
[2025-06-01T16:11:14.511+0000] {task_command.py:410} INFO - Running <TaskInstance: second_dag.save_data_task scheduled__2021-05-05T00:00:00+00:00 [running]> on host 27c4b93144a0
[2025-06-01T16:11:14.860+0000] {taskinstance.py:1547} INFO - Exporting env vars: AIRFLOW_CTX_DAG_OWNER='***' AIRFLOW_CTX_DAG_ID='second_dag' AIRFLOW_CTX_TASK_ID='save_data_task' AIRFLOW_CTX_EXECUTION_DATE='2021-05-05T00:00:00+00:00' AIRFLOW_CTX_TRY_NUMBER='2' AIRFLOW_CTX_DAG_RUN_ID='scheduled__2021-05-05T00:00:00+00:00'
[2025-06-01T16:11:14.883+0000] {my_second_dag.py:51} INFO - Fetching value USD: 75.2567
[2025-06-01T16:11:14.915+0000] {base.py:73} INFO - Using connection ID 'pg_database' for task execution.
[2025-06-01T16:11:14.942+0000] {logging_mixin.py:150} WARNING - /home/***/.local/lib/python3.7/site-packages/***/utils/context.py:313 AirflowContextDeprecationWarning: Accessing 'execution_date' from the template is deprecated and will be removed in a future version. Please use 'data_interval_start' or 'logical_date' instead.
[2025-06-01T16:11:14.949+0000] {taskinstance.py:1824} ERROR - Task failed with exception
Traceback (most recent call last):
  File "/home/airflow/.local/lib/python3.7/site-packages/sqlalchemy/engine/base.py", line 1911, in _execute_context
    cursor, statement, parameters, context
  File "/home/airflow/.local/lib/python3.7/site-packages/sqlalchemy/engine/default.py", line 736, in do_execute
    cursor.execute(statement, parameters)
psycopg2.errors.UniqueViolation: duplicate key value violates unique constraint "rub_to_usd_date_key"
DETAIL:  Key (date)=(2021-05-05 00:00:00) already exists.


The above exception was the direct cause of the following exception:

Traceback (most recent call last):
  File "/home/airflow/.local/lib/python3.7/site-packages/airflow/operators/python.py", line 181, in execute
    return_value = self.execute_callable()
  File "/home/airflow/.local/lib/python3.7/site-packages/airflow/operators/python.py", line 198, in execute_callable
    return self.python_callable(*self.op_args, **self.op_kwargs)
  File "/opt/airflow/dags/my_second_dag.py", line 65, in save_data_to_db
    VALUES ('{execution_date.date()}', {data})""")
  File "/home/airflow/.local/lib/python3.7/site-packages/sqlalchemy/engine/base.py", line 1385, in execute
    return meth(self, multiparams, params, _EMPTY_EXECUTION_OPTS)
  File "/home/airflow/.local/lib/python3.7/site-packages/sqlalchemy/sql/elements.py", line 335, in _execute_on_connection
    self, multiparams, params, execution_options
  File "/home/airflow/.local/lib/python3.7/site-packages/sqlalchemy/engine/base.py", line 1587, in _execute_clauseelement
    cache_hit=cache_hit,
  File "/home/airflow/.local/lib/python3.7/site-packages/sqlalchemy/engine/base.py", line 1954, in _execute_context
    e, statement, parameters, cursor, context
  File "/home/airflow/.local/lib/python3.7/site-packages/sqlalchemy/engine/base.py", line 2135, in _handle_dbapi_exception
    sqlalchemy_exception, with_traceback=exc_info[2], from_=e
  File "/home/airflow/.local/lib/python3.7/site-packages/sqlalchemy/util/compat.py", line 211, in raise_
    raise exception
  File "/home/airflow/.local/lib/python3.7/site-packages/sqlalchemy/engine/base.py", line 1911, in _execute_context
    cursor, statement, parameters, context
  File "/home/airflow/.local/lib/python3.7/site-packages/sqlalchemy/engine/default.py", line 736, in do_execute
    cursor.execute(statement, parameters)
sqlalchemy.exc.IntegrityError: (psycopg2.errors.UniqueViolation) duplicate key value violates unique constraint "rub_to_usd_date_key"
DETAIL:  Key (date)=(2021-05-05 00:00:00) already exists.

[SQL: INSERT INTO economic.usd_to_rub_rates (date, value)
                 VALUES ('2021-05-05', 75.2567)]
(Background on this error at: https://sqlalche.me/e/14/gkpj)
[2025-06-01T16:11:14.971+0000] {taskinstance.py:1350} INFO - Marking task as UP_FOR_RETRY. dag_id=second_dag, task_id=save_data_task, execution_date=20210505T000000, start_date=20250601T161114, end_date=20250601T161114
[2025-06-01T16:11:15.012+0000] {standard_task_runner.py:109} ERROR - Failed to execute job 1593 for task save_data_task ((psycopg2.errors.UniqueViolation) duplicate key value violates unique constraint "rub_to_usd_date_key"
DETAIL:  Key (date)=(2021-05-05 00:00:00) already exists.

[SQL: INSERT INTO economic.usd_to_rub_rates (date, value)
                 VALUES ('2021-05-05', 75.2567)]
(Background on this error at: https://sqlalche.me/e/14/gkpj); 34426)
[2025-06-01T16:11:15.034+0000] {local_task_job_runner.py:225} INFO - Task exited with return code 1
[2025-06-01T16:11:15.057+0000] {taskinstance.py:2653} INFO - 0 downstream tasks scheduled from follow-on schedule check
