[2025-06-01T15:58:20.707+0000] {taskinstance.py:1103} INFO - Dependencies all met for dep_context=non-requeueable deps ti=<TaskInstance: second_dag.save_data_task scheduled__2021-03-01T00:00:00+00:00 [queued]>
[2025-06-01T15:58:20.725+0000] {taskinstance.py:1103} INFO - Dependencies all met for dep_context=requeueable deps ti=<TaskInstance: second_dag.save_data_task scheduled__2021-03-01T00:00:00+00:00 [queued]>
[2025-06-01T15:58:20.725+0000] {taskinstance.py:1308} INFO - Starting attempt 1 of 3
[2025-06-01T15:58:20.748+0000] {taskinstance.py:1327} INFO - Executing <Task(PythonOperator): save_data_task> on 2021-03-01 00:00:00+00:00
[2025-06-01T15:58:20.754+0000] {standard_task_runner.py:57} INFO - Started process 30082 to run task
[2025-06-01T15:58:20.758+0000] {standard_task_runner.py:84} INFO - Running: ['***', 'tasks', 'run', 'second_dag', 'save_data_task', 'scheduled__2021-03-01T00:00:00+00:00', '--job-id', '1332', '--raw', '--subdir', 'DAGS_FOLDER/my_second_dag.py', '--cfg-path', '/tmp/tmpasukpr16']
[2025-06-01T15:58:20.760+0000] {standard_task_runner.py:85} INFO - Job 1332: Subtask save_data_task
[2025-06-01T15:58:20.815+0000] {task_command.py:410} INFO - Running <TaskInstance: second_dag.save_data_task scheduled__2021-03-01T00:00:00+00:00 [running]> on host 27c4b93144a0
[2025-06-01T15:58:21.082+0000] {taskinstance.py:1547} INFO - Exporting env vars: AIRFLOW_CTX_DAG_OWNER='***' AIRFLOW_CTX_DAG_ID='second_dag' AIRFLOW_CTX_TASK_ID='save_data_task' AIRFLOW_CTX_EXECUTION_DATE='2021-03-01T00:00:00+00:00' AIRFLOW_CTX_TRY_NUMBER='1' AIRFLOW_CTX_DAG_RUN_ID='scheduled__2021-03-01T00:00:00+00:00'
[2025-06-01T15:58:21.093+0000] {my_second_dag.py:51} INFO - Fetching value USD: 74.4373
[2025-06-01T15:58:21.100+0000] {base.py:73} INFO - Using connection ID 'pg_database' for task execution.
[2025-06-01T15:58:21.110+0000] {logging_mixin.py:150} WARNING - /home/***/.local/lib/python3.7/site-packages/***/utils/context.py:313 AirflowContextDeprecationWarning: Accessing 'execution_date' from the template is deprecated and will be removed in a future version. Please use 'data_interval_start' or 'logical_date' instead.
[2025-06-01T15:58:21.110+0000] {taskinstance.py:1824} ERROR - Task failed with exception
Traceback (most recent call last):
  File "/home/airflow/.local/lib/python3.7/site-packages/airflow/operators/python.py", line 181, in execute
    return_value = self.execute_callable()
  File "/home/airflow/.local/lib/python3.7/site-packages/airflow/operators/python.py", line 198, in execute_callable
    return self.python_callable(*self.op_args, **self.op_kwargs)
  File "/opt/airflow/dags/my_second_dag.py", line 65, in save_data_to_db
    VALUES ({execution_date}, {data.strftime("%Y-%m-%d")})""")
AttributeError: 'float' object has no attribute 'strftime'
[2025-06-01T15:58:21.118+0000] {taskinstance.py:1350} INFO - Marking task as UP_FOR_RETRY. dag_id=second_dag, task_id=save_data_task, execution_date=20210301T000000, start_date=20250601T155820, end_date=20250601T155821
[2025-06-01T15:58:21.128+0000] {standard_task_runner.py:109} ERROR - Failed to execute job 1332 for task save_data_task ('float' object has no attribute 'strftime'; 30082)
[2025-06-01T15:58:21.171+0000] {local_task_job_runner.py:225} INFO - Task exited with return code 1
[2025-06-01T15:58:21.187+0000] {taskinstance.py:2653} INFO - 0 downstream tasks scheduled from follow-on schedule check
