[2025-06-01T15:57:18.169+0000] {taskinstance.py:1103} INFO - Dependencies all met for dep_context=non-requeueable deps ti=<TaskInstance: second_dag.save_data_task scheduled__2021-02-05T00:00:00+00:00 [queued]>
[2025-06-01T15:57:18.181+0000] {taskinstance.py:1103} INFO - Dependencies all met for dep_context=requeueable deps ti=<TaskInstance: second_dag.save_data_task scheduled__2021-02-05T00:00:00+00:00 [queued]>
[2025-06-01T15:57:18.182+0000] {taskinstance.py:1308} INFO - Starting attempt 1 of 3
[2025-06-01T15:57:18.213+0000] {taskinstance.py:1327} INFO - Executing <Task(PythonOperator): save_data_task> on 2021-02-05 00:00:00+00:00
[2025-06-01T15:57:18.222+0000] {standard_task_runner.py:57} INFO - Started process 28359 to run task
[2025-06-01T15:57:18.225+0000] {standard_task_runner.py:84} INFO - Running: ['***', 'tasks', 'run', 'second_dag', 'save_data_task', 'scheduled__2021-02-05T00:00:00+00:00', '--job-id', '1212', '--raw', '--subdir', 'DAGS_FOLDER/my_second_dag.py', '--cfg-path', '/tmp/tmp41ad56tm']
[2025-06-01T15:57:18.226+0000] {standard_task_runner.py:85} INFO - Job 1212: Subtask save_data_task
[2025-06-01T15:57:18.279+0000] {task_command.py:410} INFO - Running <TaskInstance: second_dag.save_data_task scheduled__2021-02-05T00:00:00+00:00 [running]> on host 27c4b93144a0
[2025-06-01T15:57:18.542+0000] {taskinstance.py:1547} INFO - Exporting env vars: AIRFLOW_CTX_DAG_OWNER='***' AIRFLOW_CTX_DAG_ID='second_dag' AIRFLOW_CTX_TASK_ID='save_data_task' AIRFLOW_CTX_EXECUTION_DATE='2021-02-05T00:00:00+00:00' AIRFLOW_CTX_TRY_NUMBER='1' AIRFLOW_CTX_DAG_RUN_ID='scheduled__2021-02-05T00:00:00+00:00'
[2025-06-01T15:57:18.550+0000] {my_second_dag.py:51} INFO - Fetching value USD: 75.7293
[2025-06-01T15:57:18.557+0000] {base.py:73} INFO - Using connection ID 'pg_database' for task execution.
[2025-06-01T15:57:18.565+0000] {logging_mixin.py:150} WARNING - /home/***/.local/lib/python3.7/site-packages/***/utils/context.py:313 AirflowContextDeprecationWarning: Accessing 'execution_date' from the template is deprecated and will be removed in a future version. Please use 'data_interval_start' or 'logical_date' instead.
[2025-06-01T15:57:18.566+0000] {taskinstance.py:1824} ERROR - Task failed with exception
Traceback (most recent call last):
  File "/home/airflow/.local/lib/python3.7/site-packages/airflow/operators/python.py", line 181, in execute
    return_value = self.execute_callable()
  File "/home/airflow/.local/lib/python3.7/site-packages/airflow/operators/python.py", line 198, in execute_callable
    return self.python_callable(*self.op_args, **self.op_kwargs)
  File "/opt/airflow/dags/my_second_dag.py", line 65, in save_data_to_db
    VALUES ({execution_date}, {data.strftime("%Y-%m-%d")})""")
AttributeError: 'float' object has no attribute 'strftime'
[2025-06-01T15:57:18.573+0000] {taskinstance.py:1350} INFO - Marking task as UP_FOR_RETRY. dag_id=second_dag, task_id=save_data_task, execution_date=20210205T000000, start_date=20250601T155718, end_date=20250601T155718
[2025-06-01T15:57:18.581+0000] {standard_task_runner.py:109} ERROR - Failed to execute job 1212 for task save_data_task ('float' object has no attribute 'strftime'; 28359)
[2025-06-01T15:57:18.601+0000] {local_task_job_runner.py:225} INFO - Task exited with return code 1
[2025-06-01T15:57:18.621+0000] {taskinstance.py:2653} INFO - 0 downstream tasks scheduled from follow-on schedule check
