[2025-06-01T16:32:36.672+0000] {taskinstance.py:1103} INFO - Dependencies all met for dep_context=non-requeueable deps ti=<TaskInstance: second_dag.fetch_data_task scheduled__2023-06-21T00:00:00+00:00 [queued]>
[2025-06-01T16:32:36.680+0000] {taskinstance.py:1103} INFO - Dependencies all met for dep_context=requeueable deps ti=<TaskInstance: second_dag.fetch_data_task scheduled__2023-06-21T00:00:00+00:00 [queued]>
[2025-06-01T16:32:36.680+0000] {taskinstance.py:1308} INFO - Starting attempt 1 of 3
[2025-06-01T16:32:36.699+0000] {taskinstance.py:1327} INFO - Executing <Task(PythonOperator): fetch_data_task> on 2023-06-21 00:00:00+00:00
[2025-06-01T16:32:36.719+0000] {standard_task_runner.py:57} INFO - Started process 58030 to run task
[2025-06-01T16:32:36.725+0000] {standard_task_runner.py:84} INFO - Running: ['***', 'tasks', 'run', 'second_dag', 'fetch_data_task', 'scheduled__2023-06-21T00:00:00+00:00', '--job-id', '3213', '--raw', '--subdir', 'DAGS_FOLDER/my_second_dag.py', '--cfg-path', '/tmp/tmpzop4o9lm']
[2025-06-01T16:32:36.726+0000] {standard_task_runner.py:85} INFO - Job 3213: Subtask fetch_data_task
[2025-06-01T16:32:36.796+0000] {task_command.py:410} INFO - Running <TaskInstance: second_dag.fetch_data_task scheduled__2023-06-21T00:00:00+00:00 [running]> on host 27c4b93144a0
[2025-06-01T16:32:37.120+0000] {taskinstance.py:1547} INFO - Exporting env vars: AIRFLOW_CTX_DAG_OWNER='***' AIRFLOW_CTX_DAG_ID='second_dag' AIRFLOW_CTX_TASK_ID='fetch_data_task' AIRFLOW_CTX_EXECUTION_DATE='2023-06-21T00:00:00+00:00' AIRFLOW_CTX_TRY_NUMBER='1' AIRFLOW_CTX_DAG_RUN_ID='scheduled__2023-06-21T00:00:00+00:00'
[2025-06-01T16:32:37.126+0000] {logging_mixin.py:150} WARNING - /home/***/.local/lib/python3.7/site-packages/***/utils/context.py:313 AirflowContextDeprecationWarning: Accessing 'execution_date' from the template is deprecated and will be removed in a future version. Please use 'data_interval_start' or 'logical_date' instead.
[2025-06-01T16:32:37.127+0000] {my_second_dag.py:22} INFO - execution_date : 2023-06-21T00:00:00+00:00
[2025-06-01T16:32:37.127+0000] {my_second_dag.py:24} INFO - Fetching data for date: 21/06/2023
[2025-06-01T16:32:58.186+0000] {taskinstance.py:1824} ERROR - Task failed with exception
Traceback (most recent call last):
  File "/home/airflow/.local/lib/python3.7/site-packages/urllib3/connection.py", line 175, in _new_conn
    (self._dns_host, self.port), self.timeout, **extra_kw
  File "/home/airflow/.local/lib/python3.7/site-packages/urllib3/util/connection.py", line 95, in create_connection
    raise err
  File "/home/airflow/.local/lib/python3.7/site-packages/urllib3/util/connection.py", line 85, in create_connection
    sock.connect(sa)
ConnectionRefusedError: [Errno 111] Connection refused

During handling of the above exception, another exception occurred:

Traceback (most recent call last):
  File "/home/airflow/.local/lib/python3.7/site-packages/urllib3/connectionpool.py", line 721, in urlopen
    chunked=chunked,
  File "/home/airflow/.local/lib/python3.7/site-packages/urllib3/connectionpool.py", line 415, in _make_request
    conn.request(method, url, **httplib_request_kw)
  File "/home/airflow/.local/lib/python3.7/site-packages/urllib3/connection.py", line 244, in request
    super(HTTPConnection, self).request(method, url, body=body, headers=headers)
  File "/usr/local/lib/python3.7/http/client.py", line 1281, in request
    self._send_request(method, url, body, headers, encode_chunked)
  File "/usr/local/lib/python3.7/http/client.py", line 1327, in _send_request
    self.endheaders(body, encode_chunked=encode_chunked)
  File "/usr/local/lib/python3.7/http/client.py", line 1276, in endheaders
    self._send_output(message_body, encode_chunked=encode_chunked)
  File "/usr/local/lib/python3.7/http/client.py", line 1036, in _send_output
    self.send(msg)
  File "/usr/local/lib/python3.7/http/client.py", line 976, in send
    self.connect()
  File "/home/airflow/.local/lib/python3.7/site-packages/urllib3/connection.py", line 205, in connect
    conn = self._new_conn()
  File "/home/airflow/.local/lib/python3.7/site-packages/urllib3/connection.py", line 187, in _new_conn
    self, "Failed to establish a new connection: %s" % e
urllib3.exceptions.NewConnectionError: <urllib3.connection.HTTPConnection object at 0x7fdcc29528d0>: Failed to establish a new connection: [Errno 111] Connection refused

During handling of the above exception, another exception occurred:

Traceback (most recent call last):
  File "/home/airflow/.local/lib/python3.7/site-packages/requests/adapters.py", line 497, in send
    chunked=chunked,
  File "/home/airflow/.local/lib/python3.7/site-packages/urllib3/connectionpool.py", line 799, in urlopen
    method, url, error=e, _pool=self, _stacktrace=sys.exc_info()[2]
  File "/home/airflow/.local/lib/python3.7/site-packages/urllib3/util/retry.py", line 592, in increment
    raise MaxRetryError(_pool, url, error or ResponseError(cause))
urllib3.exceptions.MaxRetryError: HTTPConnectionPool(host='www.cbr.ru', port=80): Max retries exceeded with url: /scripts/XML_daily.asp?date_req=21/06/2023 (Caused by NewConnectionError('<urllib3.connection.HTTPConnection object at 0x7fdcc29528d0>: Failed to establish a new connection: [Errno 111] Connection refused'))

During handling of the above exception, another exception occurred:

Traceback (most recent call last):
  File "/home/airflow/.local/lib/python3.7/site-packages/airflow/operators/python.py", line 181, in execute
    return_value = self.execute_callable()
  File "/home/airflow/.local/lib/python3.7/site-packages/airflow/operators/python.py", line 198, in execute_callable
    return self.python_callable(*self.op_args, **self.op_kwargs)
  File "/opt/airflow/dags/my_second_dag.py", line 29, in fetch_data_from_api
    response = requests.get(url)
  File "/home/airflow/.local/lib/python3.7/site-packages/requests/api.py", line 73, in get
    return request("get", url, params=params, **kwargs)
  File "/home/airflow/.local/lib/python3.7/site-packages/requests/api.py", line 59, in request
    return session.request(method=method, url=url, **kwargs)
  File "/home/airflow/.local/lib/python3.7/site-packages/requests/sessions.py", line 589, in request
    resp = self.send(prep, **send_kwargs)
  File "/home/airflow/.local/lib/python3.7/site-packages/requests/sessions.py", line 703, in send
    r = adapter.send(request, **kwargs)
  File "/home/airflow/.local/lib/python3.7/site-packages/requests/adapters.py", line 519, in send
    raise ConnectionError(e, request=request)
requests.exceptions.ConnectionError: HTTPConnectionPool(host='www.cbr.ru', port=80): Max retries exceeded with url: /scripts/XML_daily.asp?date_req=21/06/2023 (Caused by NewConnectionError('<urllib3.connection.HTTPConnection object at 0x7fdcc29528d0>: Failed to establish a new connection: [Errno 111] Connection refused'))
[2025-06-01T16:32:58.202+0000] {taskinstance.py:1350} INFO - Marking task as UP_FOR_RETRY. dag_id=second_dag, task_id=fetch_data_task, execution_date=20230621T000000, start_date=20250601T163236, end_date=20250601T163258
[2025-06-01T16:32:58.212+0000] {standard_task_runner.py:109} ERROR - Failed to execute job 3213 for task fetch_data_task (HTTPConnectionPool(host='www.cbr.ru', port=80): Max retries exceeded with url: /scripts/XML_daily.asp?date_req=21/06/2023 (Caused by NewConnectionError('<urllib3.connection.HTTPConnection object at 0x7fdcc29528d0>: Failed to establish a new connection: [Errno 111] Connection refused')); 58030)
[2025-06-01T16:32:58.264+0000] {local_task_job_runner.py:225} INFO - Task exited with return code 1
[2025-06-01T16:32:58.379+0000] {taskinstance.py:2653} INFO - 0 downstream tasks scheduled from follow-on schedule check
