[2025-06-01T16:12:23.536+0000] {taskinstance.py:1103} INFO - Dependencies all met for dep_context=non-requeueable deps ti=<TaskInstance: second_dag.save_data_task scheduled__2021-06-11T00:00:00+00:00 [queued]>
[2025-06-01T16:12:23.543+0000] {taskinstance.py:1103} INFO - Dependencies all met for dep_context=requeueable deps ti=<TaskInstance: second_dag.save_data_task scheduled__2021-06-11T00:00:00+00:00 [queued]>
[2025-06-01T16:12:23.543+0000] {taskinstance.py:1308} INFO - Starting attempt 1 of 3
[2025-06-01T16:12:23.553+0000] {taskinstance.py:1327} INFO - Executing <Task(PythonOperator): save_data_task> on 2021-06-11 00:00:00+00:00
[2025-06-01T16:12:23.559+0000] {standard_task_runner.py:57} INFO - Started process 36250 to run task
[2025-06-01T16:12:23.561+0000] {standard_task_runner.py:84} INFO - Running: ['***', 'tasks', 'run', 'second_dag', 'save_data_task', 'scheduled__2021-06-11T00:00:00+00:00', '--job-id', '1728', '--raw', '--subdir', 'DAGS_FOLDER/my_second_dag.py', '--cfg-path', '/tmp/tmpnje862k_']
[2025-06-01T16:12:23.562+0000] {standard_task_runner.py:85} INFO - Job 1728: Subtask save_data_task
[2025-06-01T16:12:23.595+0000] {task_command.py:410} INFO - Running <TaskInstance: second_dag.save_data_task scheduled__2021-06-11T00:00:00+00:00 [running]> on host 27c4b93144a0
[2025-06-01T16:12:23.759+0000] {taskinstance.py:1547} INFO - Exporting env vars: AIRFLOW_CTX_DAG_OWNER='***' AIRFLOW_CTX_DAG_ID='second_dag' AIRFLOW_CTX_TASK_ID='save_data_task' AIRFLOW_CTX_EXECUTION_DATE='2021-06-11T00:00:00+00:00' AIRFLOW_CTX_TRY_NUMBER='1' AIRFLOW_CTX_DAG_RUN_ID='scheduled__2021-06-11T00:00:00+00:00'
[2025-06-01T16:12:23.768+0000] {my_second_dag.py:51} INFO - Fetching value USD: 72.1974
[2025-06-01T16:12:23.773+0000] {base.py:73} INFO - Using connection ID 'pg_database' for task execution.
[2025-06-01T16:12:23.781+0000] {logging_mixin.py:150} WARNING - /home/***/.local/lib/python3.7/site-packages/***/utils/context.py:313 AirflowContextDeprecationWarning: Accessing 'execution_date' from the template is deprecated and will be removed in a future version. Please use 'data_interval_start' or 'logical_date' instead.
[2025-06-01T16:12:23.782+0000] {taskinstance.py:1824} ERROR - Task failed with exception
Traceback (most recent call last):
  File "/home/airflow/.local/lib/python3.7/site-packages/airflow/operators/python.py", line 181, in execute
    return_value = self.execute_callable()
  File "/home/airflow/.local/lib/python3.7/site-packages/airflow/operators/python.py", line 198, in execute_callable
    return self.python_callable(*self.op_args, **self.op_kwargs)
  File "/opt/airflow/dags/my_second_dag.py", line 67, in save_data_to_db
    conn.commit()
AttributeError: 'Connection' object has no attribute 'commit'
[2025-06-01T16:12:23.788+0000] {taskinstance.py:1350} INFO - Marking task as UP_FOR_RETRY. dag_id=second_dag, task_id=save_data_task, execution_date=20210611T000000, start_date=20250601T161223, end_date=20250601T161223
[2025-06-01T16:12:23.795+0000] {standard_task_runner.py:109} ERROR - Failed to execute job 1728 for task save_data_task ('Connection' object has no attribute 'commit'; 36250)
[2025-06-01T16:12:23.813+0000] {local_task_job_runner.py:225} INFO - Task exited with return code 1
[2025-06-01T16:12:23.827+0000] {taskinstance.py:2653} INFO - 0 downstream tasks scheduled from follow-on schedule check
