[2025-06-01T17:56:49.891+0000] {taskinstance.py:1103} INFO - Dependencies all met for dep_context=non-requeueable deps ti=<TaskInstance: second_dag.save_data_task scheduled__2000-05-31T00:00:00+00:00 [queued]>
[2025-06-01T17:56:50.022+0000] {taskinstance.py:1103} INFO - Dependencies all met for dep_context=requeueable deps ti=<TaskInstance: second_dag.save_data_task scheduled__2000-05-31T00:00:00+00:00 [queued]>
[2025-06-01T17:56:50.022+0000] {taskinstance.py:1308} INFO - Starting attempt 1 of 3
[2025-06-01T17:56:50.042+0000] {taskinstance.py:1327} INFO - Executing <Task(PythonOperator): save_data_task> on 2000-05-31 00:00:00+00:00
[2025-06-01T17:56:50.055+0000] {standard_task_runner.py:57} INFO - Started process 4736 to run task
[2025-06-01T17:56:50.059+0000] {standard_task_runner.py:84} INFO - Running: ['***', 'tasks', 'run', 'second_dag', 'save_data_task', 'scheduled__2000-05-31T00:00:00+00:00', '--job-id', '4956', '--raw', '--subdir', 'DAGS_FOLDER/my_second_dag.py', '--cfg-path', '/tmp/tmpn5nfc37g']
[2025-06-01T17:56:50.061+0000] {standard_task_runner.py:85} INFO - Job 4956: Subtask save_data_task
[2025-06-01T17:56:50.098+0000] {task_command.py:410} INFO - Running <TaskInstance: second_dag.save_data_task scheduled__2000-05-31T00:00:00+00:00 [running]> on host 40869fde016f
[2025-06-01T17:56:50.210+0000] {taskinstance.py:1547} INFO - Exporting env vars: AIRFLOW_CTX_DAG_OWNER='***' AIRFLOW_CTX_DAG_ID='second_dag' AIRFLOW_CTX_TASK_ID='save_data_task' AIRFLOW_CTX_EXECUTION_DATE='2000-05-31T00:00:00+00:00' AIRFLOW_CTX_TRY_NUMBER='1' AIRFLOW_CTX_DAG_RUN_ID='scheduled__2000-05-31T00:00:00+00:00'
[2025-06-01T17:56:50.221+0000] {my_second_dag.py:51} INFO - Fetching value USD: 28.25
[2025-06-01T17:56:50.229+0000] {base.py:73} INFO - Using connection ID 'pg_database' for task execution.
[2025-06-01T17:56:50.239+0000] {logging_mixin.py:150} WARNING - /home/***/.local/lib/python3.7/site-packages/***/utils/context.py:313 AirflowContextDeprecationWarning: Accessing 'execution_date' from the template is deprecated and will be removed in a future version. Please use 'data_interval_start' or 'logical_date' instead.
[2025-06-01T17:56:50.241+0000] {my_second_dag.py:69} INFO - Data saved successfully.
[2025-06-01T17:56:50.241+0000] {python.py:183} INFO - Done. Returned value was: None
[2025-06-01T17:56:50.251+0000] {taskinstance.py:1350} INFO - Marking task as SUCCESS. dag_id=second_dag, task_id=save_data_task, execution_date=20000531T000000, start_date=20250601T175649, end_date=20250601T175650
[2025-06-01T17:56:50.313+0000] {local_task_job_runner.py:225} INFO - Task exited with return code 0
[2025-06-01T17:56:50.332+0000] {taskinstance.py:2653} INFO - 0 downstream tasks scheduled from follow-on schedule check
