[2025-06-01T16:36:20.264+0000] {taskinstance.py:1103} INFO - Dependencies all met for dep_context=non-requeueable deps ti=<TaskInstance: second_dag.save_data_task scheduled__2024-10-17T00:00:00+00:00 [queued]>
[2025-06-01T16:36:20.280+0000] {taskinstance.py:1103} INFO - Dependencies all met for dep_context=requeueable deps ti=<TaskInstance: second_dag.save_data_task scheduled__2024-10-17T00:00:00+00:00 [queued]>
[2025-06-01T16:36:20.280+0000] {taskinstance.py:1308} INFO - Starting attempt 1 of 3
[2025-06-01T16:36:20.296+0000] {taskinstance.py:1327} INFO - Executing <Task(PythonOperator): save_data_task> on 2024-10-17 00:00:00+00:00
[2025-06-01T16:36:20.305+0000] {standard_task_runner.py:57} INFO - Started process 71954 to run task
[2025-06-01T16:36:20.313+0000] {standard_task_runner.py:84} INFO - Running: ['***', 'tasks', 'run', 'second_dag', 'save_data_task', 'scheduled__2024-10-17T00:00:00+00:00', '--job-id', '4201', '--raw', '--subdir', 'DAGS_FOLDER/my_second_dag.py', '--cfg-path', '/tmp/tmpmb75xyzr']
[2025-06-01T16:36:20.319+0000] {standard_task_runner.py:85} INFO - Job 4201: Subtask save_data_task
[2025-06-01T16:36:20.404+0000] {task_command.py:410} INFO - Running <TaskInstance: second_dag.save_data_task scheduled__2024-10-17T00:00:00+00:00 [running]> on host 27c4b93144a0
[2025-06-01T16:36:20.678+0000] {taskinstance.py:1547} INFO - Exporting env vars: AIRFLOW_CTX_DAG_OWNER='***' AIRFLOW_CTX_DAG_ID='second_dag' AIRFLOW_CTX_TASK_ID='save_data_task' AIRFLOW_CTX_EXECUTION_DATE='2024-10-17T00:00:00+00:00' AIRFLOW_CTX_TRY_NUMBER='1' AIRFLOW_CTX_DAG_RUN_ID='scheduled__2024-10-17T00:00:00+00:00'
[2025-06-01T16:36:20.689+0000] {my_second_dag.py:51} INFO - Fetching value USD: 97.2568
[2025-06-01T16:36:20.695+0000] {base.py:73} INFO - Using connection ID 'pg_database' for task execution.
[2025-06-01T16:36:20.704+0000] {logging_mixin.py:150} WARNING - /home/***/.local/lib/python3.7/site-packages/***/utils/context.py:313 AirflowContextDeprecationWarning: Accessing 'execution_date' from the template is deprecated and will be removed in a future version. Please use 'data_interval_start' or 'logical_date' instead.
[2025-06-01T16:36:20.706+0000] {my_second_dag.py:69} INFO - Data saved successfully.
[2025-06-01T16:36:20.707+0000] {python.py:183} INFO - Done. Returned value was: None
[2025-06-01T16:36:20.714+0000] {taskinstance.py:1350} INFO - Marking task as SUCCESS. dag_id=second_dag, task_id=save_data_task, execution_date=20241017T000000, start_date=20250601T163620, end_date=20250601T163620
[2025-06-01T16:36:20.766+0000] {local_task_job_runner.py:225} INFO - Task exited with return code 0
[2025-06-01T16:36:20.795+0000] {taskinstance.py:2653} INFO - 0 downstream tasks scheduled from follow-on schedule check
