[2025-06-01T09:51:00.028+0000] {taskinstance.py:1103} INFO - Dependencies all met for dep_context=non-requeueable deps ti=<TaskInstance: first_dag.random_dice scheduled__2021-03-13T00:00:00+00:00 [queued]>
[2025-06-01T09:51:00.037+0000] {taskinstance.py:1103} INFO - Dependencies all met for dep_context=requeueable deps ti=<TaskInstance: first_dag.random_dice scheduled__2021-03-13T00:00:00+00:00 [queued]>
[2025-06-01T09:51:00.038+0000] {taskinstance.py:1308} INFO - Starting attempt 2 of 3
[2025-06-01T09:51:00.052+0000] {taskinstance.py:1327} INFO - Executing <Task(PythonOperator): random_dice> on 2021-03-13 00:00:00+00:00
[2025-06-01T09:51:00.057+0000] {standard_task_runner.py:57} INFO - Started process 4043 to run task
[2025-06-01T09:51:00.060+0000] {standard_task_runner.py:84} INFO - Running: ['***', 'tasks', 'run', 'first_dag', 'random_dice', 'scheduled__2021-03-13T00:00:00+00:00', '--job-id', '134', '--raw', '--subdir', 'DAGS_FOLDER/my_first_dag.py', '--cfg-path', '/tmp/tmpb3r_a07o']
[2025-06-01T09:51:00.061+0000] {standard_task_runner.py:85} INFO - Job 134: Subtask random_dice
[2025-06-01T09:51:00.097+0000] {task_command.py:410} INFO - Running <TaskInstance: first_dag.random_dice scheduled__2021-03-13T00:00:00+00:00 [running]> on host 27c4b93144a0
[2025-06-01T09:51:00.182+0000] {taskinstance.py:1547} INFO - Exporting env vars: AIRFLOW_CTX_DAG_OWNER='***' AIRFLOW_CTX_DAG_ID='first_dag' AIRFLOW_CTX_TASK_ID='random_dice' AIRFLOW_CTX_EXECUTION_DATE='2021-03-13T00:00:00+00:00' AIRFLOW_CTX_TRY_NUMBER='2' AIRFLOW_CTX_DAG_RUN_ID='scheduled__2021-03-13T00:00:00+00:00'
[2025-06-01T09:51:00.182+0000] {taskinstance.py:1824} ERROR - Task failed with exception
Traceback (most recent call last):
  File "/home/airflow/.local/lib/python3.7/site-packages/airflow/operators/python.py", line 181, in execute
    return_value = self.execute_callable()
  File "/home/airflow/.local/lib/python3.7/site-packages/airflow/operators/python.py", line 198, in execute_callable
    return self.python_callable(*self.op_args, **self.op_kwargs)
  File "/opt/airflow/dags/my_first_dag.py", line 18, in random_dice
    raise ValueError(f'Odd {val}')
ValueError: Odd 1
[2025-06-01T09:51:00.193+0000] {taskinstance.py:1350} INFO - Marking task as UP_FOR_RETRY. dag_id=first_dag, task_id=random_dice, execution_date=20210313T000000, start_date=20250601T095100, end_date=20250601T095100
[2025-06-01T09:51:00.203+0000] {standard_task_runner.py:109} ERROR - Failed to execute job 134 for task random_dice (Odd 1; 4043)
[2025-06-01T09:51:00.231+0000] {local_task_job_runner.py:225} INFO - Task exited with return code 1
[2025-06-01T09:51:00.341+0000] {taskinstance.py:2653} INFO - 0 downstream tasks scheduled from follow-on schedule check
