[2025-06-01T15:59:59.095+0000] {taskinstance.py:1103} INFO - Dependencies all met for dep_context=non-requeueable deps ti=<TaskInstance: second_dag.save_data_task scheduled__2021-02-28T00:00:00+00:00 [queued]>
[2025-06-01T15:59:59.106+0000] {taskinstance.py:1103} INFO - Dependencies all met for dep_context=requeueable deps ti=<TaskInstance: second_dag.save_data_task scheduled__2021-02-28T00:00:00+00:00 [queued]>
[2025-06-01T15:59:59.106+0000] {taskinstance.py:1308} INFO - Starting attempt 3 of 3
[2025-06-01T15:59:59.124+0000] {taskinstance.py:1327} INFO - Executing <Task(PythonOperator): save_data_task> on 2021-02-28 00:00:00+00:00
[2025-06-01T15:59:59.132+0000] {standard_task_runner.py:57} INFO - Started process 30604 to run task
[2025-06-01T15:59:59.136+0000] {standard_task_runner.py:84} INFO - Running: ['***', 'tasks', 'run', 'second_dag', 'save_data_task', 'scheduled__2021-02-28T00:00:00+00:00', '--job-id', '1355', '--raw', '--subdir', 'DAGS_FOLDER/my_second_dag.py', '--cfg-path', '/tmp/tmpzofnlw40']
[2025-06-01T15:59:59.143+0000] {standard_task_runner.py:85} INFO - Job 1355: Subtask save_data_task
[2025-06-01T15:59:59.237+0000] {task_command.py:410} INFO - Running <TaskInstance: second_dag.save_data_task scheduled__2021-02-28T00:00:00+00:00 [running]> on host 27c4b93144a0
[2025-06-01T15:59:59.625+0000] {taskinstance.py:1547} INFO - Exporting env vars: AIRFLOW_CTX_DAG_OWNER='***' AIRFLOW_CTX_DAG_ID='second_dag' AIRFLOW_CTX_TASK_ID='save_data_task' AIRFLOW_CTX_EXECUTION_DATE='2021-02-28T00:00:00+00:00' AIRFLOW_CTX_TRY_NUMBER='3' AIRFLOW_CTX_DAG_RUN_ID='scheduled__2021-02-28T00:00:00+00:00'
[2025-06-01T15:59:59.666+0000] {my_second_dag.py:51} INFO - Fetching value USD: 74.4373
[2025-06-01T15:59:59.678+0000] {base.py:73} INFO - Using connection ID 'pg_database' for task execution.
[2025-06-01T15:59:59.690+0000] {logging_mixin.py:150} WARNING - /home/***/.local/lib/python3.7/site-packages/***/utils/context.py:313 AirflowContextDeprecationWarning: Accessing 'execution_date' from the template is deprecated and will be removed in a future version. Please use 'data_interval_start' or 'logical_date' instead.
[2025-06-01T15:59:59.692+0000] {taskinstance.py:1824} ERROR - Task failed with exception
Traceback (most recent call last):
  File "/home/airflow/.local/lib/python3.7/site-packages/sqlalchemy/engine/base.py", line 1911, in _execute_context
    cursor, statement, parameters, context
  File "/home/airflow/.local/lib/python3.7/site-packages/sqlalchemy/engine/default.py", line 736, in do_execute
    cursor.execute(statement, parameters)
psycopg2.errors.UndefinedTable: relation "usd_to_rub_rates" does not exist
LINE 1: INSERT INTO usd_to_rub_rates (date, value)
                    ^


The above exception was the direct cause of the following exception:

Traceback (most recent call last):
  File "/home/airflow/.local/lib/python3.7/site-packages/airflow/operators/python.py", line 181, in execute
    return_value = self.execute_callable()
  File "/home/airflow/.local/lib/python3.7/site-packages/airflow/operators/python.py", line 198, in execute_callable
    return self.python_callable(*self.op_args, **self.op_kwargs)
  File "/opt/airflow/dags/my_second_dag.py", line 65, in save_data_to_db
    VALUES ({execution_date.strftime("%Y-%m-%d")}, {data})""")
  File "/home/airflow/.local/lib/python3.7/site-packages/sqlalchemy/engine/base.py", line 1385, in execute
    return meth(self, multiparams, params, _EMPTY_EXECUTION_OPTS)
  File "/home/airflow/.local/lib/python3.7/site-packages/sqlalchemy/sql/elements.py", line 335, in _execute_on_connection
    self, multiparams, params, execution_options
  File "/home/airflow/.local/lib/python3.7/site-packages/sqlalchemy/engine/base.py", line 1587, in _execute_clauseelement
    cache_hit=cache_hit,
  File "/home/airflow/.local/lib/python3.7/site-packages/sqlalchemy/engine/base.py", line 1954, in _execute_context
    e, statement, parameters, cursor, context
  File "/home/airflow/.local/lib/python3.7/site-packages/sqlalchemy/engine/base.py", line 2135, in _handle_dbapi_exception
    sqlalchemy_exception, with_traceback=exc_info[2], from_=e
  File "/home/airflow/.local/lib/python3.7/site-packages/sqlalchemy/util/compat.py", line 211, in raise_
    raise exception
  File "/home/airflow/.local/lib/python3.7/site-packages/sqlalchemy/engine/base.py", line 1911, in _execute_context
    cursor, statement, parameters, context
  File "/home/airflow/.local/lib/python3.7/site-packages/sqlalchemy/engine/default.py", line 736, in do_execute
    cursor.execute(statement, parameters)
sqlalchemy.exc.ProgrammingError: (psycopg2.errors.UndefinedTable) relation "usd_to_rub_rates" does not exist
LINE 1: INSERT INTO usd_to_rub_rates (date, value)
                    ^

[SQL: INSERT INTO usd_to_rub_rates (date, value)
                 VALUES (2021-02-28, 74.4373)]
(Background on this error at: https://sqlalche.me/e/14/f405)
[2025-06-01T15:59:59.710+0000] {taskinstance.py:1350} INFO - Marking task as FAILED. dag_id=second_dag, task_id=save_data_task, execution_date=20210228T000000, start_date=20250601T155959, end_date=20250601T155959
[2025-06-01T15:59:59.723+0000] {standard_task_runner.py:109} ERROR - Failed to execute job 1355 for task save_data_task ((psycopg2.errors.UndefinedTable) relation "usd_to_rub_rates" does not exist
LINE 1: INSERT INTO usd_to_rub_rates (date, value)
                    ^

[SQL: INSERT INTO usd_to_rub_rates (date, value)
                 VALUES (2021-02-28, 74.4373)]
(Background on this error at: https://sqlalche.me/e/14/f405); 30604)
[2025-06-01T15:59:59.770+0000] {local_task_job_runner.py:225} INFO - Task exited with return code 1
[2025-06-01T15:59:59.853+0000] {taskinstance.py:2653} INFO - 0 downstream tasks scheduled from follow-on schedule check
