[2025-06-01T16:33:52.382+0000] {taskinstance.py:1103} INFO - Dependencies all met for dep_context=non-requeueable deps ti=<TaskInstance: second_dag.save_data_task scheduled__2023-11-27T00:00:00+00:00 [queued]>
[2025-06-01T16:33:52.413+0000] {taskinstance.py:1103} INFO - Dependencies all met for dep_context=requeueable deps ti=<TaskInstance: second_dag.save_data_task scheduled__2023-11-27T00:00:00+00:00 [queued]>
[2025-06-01T16:33:52.414+0000] {taskinstance.py:1308} INFO - Starting attempt 1 of 3
[2025-06-01T16:33:52.501+0000] {taskinstance.py:1327} INFO - Executing <Task(PythonOperator): save_data_task> on 2023-11-27 00:00:00+00:00
[2025-06-01T16:33:52.509+0000] {standard_task_runner.py:57} INFO - Started process 62782 to run task
[2025-06-01T16:33:52.511+0000] {standard_task_runner.py:84} INFO - Running: ['***', 'tasks', 'run', 'second_dag', 'save_data_task', 'scheduled__2023-11-27T00:00:00+00:00', '--job-id', '3550', '--raw', '--subdir', 'DAGS_FOLDER/my_second_dag.py', '--cfg-path', '/tmp/tmpaerhv39k']
[2025-06-01T16:33:52.513+0000] {standard_task_runner.py:85} INFO - Job 3550: Subtask save_data_task
[2025-06-01T16:33:52.621+0000] {task_command.py:410} INFO - Running <TaskInstance: second_dag.save_data_task scheduled__2023-11-27T00:00:00+00:00 [running]> on host 27c4b93144a0
[2025-06-01T16:33:52.998+0000] {taskinstance.py:1547} INFO - Exporting env vars: AIRFLOW_CTX_DAG_OWNER='***' AIRFLOW_CTX_DAG_ID='second_dag' AIRFLOW_CTX_TASK_ID='save_data_task' AIRFLOW_CTX_EXECUTION_DATE='2023-11-27T00:00:00+00:00' AIRFLOW_CTX_TRY_NUMBER='1' AIRFLOW_CTX_DAG_RUN_ID='scheduled__2023-11-27T00:00:00+00:00'
[2025-06-01T16:33:53.014+0000] {my_second_dag.py:51} INFO - Fetching value USD: 88.8133
[2025-06-01T16:33:53.027+0000] {base.py:73} INFO - Using connection ID 'pg_database' for task execution.
[2025-06-01T16:33:53.041+0000] {logging_mixin.py:150} WARNING - /home/***/.local/lib/python3.7/site-packages/***/utils/context.py:313 AirflowContextDeprecationWarning: Accessing 'execution_date' from the template is deprecated and will be removed in a future version. Please use 'data_interval_start' or 'logical_date' instead.
[2025-06-01T16:33:53.046+0000] {my_second_dag.py:69} INFO - Data saved successfully.
[2025-06-01T16:33:53.046+0000] {python.py:183} INFO - Done. Returned value was: None
[2025-06-01T16:33:53.055+0000] {taskinstance.py:1350} INFO - Marking task as SUCCESS. dag_id=second_dag, task_id=save_data_task, execution_date=20231127T000000, start_date=20250601T163352, end_date=20250601T163353
[2025-06-01T16:33:53.128+0000] {local_task_job_runner.py:225} INFO - Task exited with return code 0
[2025-06-01T16:33:53.148+0000] {taskinstance.py:2653} INFO - 0 downstream tasks scheduled from follow-on schedule check
